<?xml version="0.0" ?>
<robot name="MPL">
	<link name="forearm">
		<inertial>
			<origin rpy="0.00000 -0.00000 0.00000" xyz="0.00000 0.00000 0.00000"/>
			<mass value="0.02513"/>
			<inertia ixx="0.00000" ixy="0" ixz="0" iyy="0.00000" iyz="0" izz="0.00001"/>
		</inertial>
		<collision>
			<origin rpy="0.00000 -0.00000 0.00000" xyz="0.00000 0.00000 0.00000"/>
			<geometry>
				<cylinder length="0.02000" radius="0.02000"/>
			</geometry>
		</collision>
	</link>
	<link name="link0_2">
		<inertial>
			<origin rpy="0.00000 -0.00000 0.00000" xyz="0.00000 0.00000 0.00000"/>
			<mass value="0.00000"/>
			<inertia ixx="0.00000" ixy="0" ixz="0" iyy="0.00000" iyz="0" izz="0.00000"/>
		</inertial>
	</link>
	<link name="wristy">
		<inertial>
			<origin rpy="-0.00695 -0.02342 1.56965" xyz="-0.00007 -0.02178 -0.00029"/>
			<mass value="0.02729"/>
			<inertia ixx="0.00011" ixy="0" ixz="0" iyy="0.00010" iyz="0" izz="0.00010"/>
		</inertial>
		<collision>
			<origin rpy="0.00000 -0.00000 0.00000" xyz="0.00000 -0.00000 0.00000"/>
			<geometry>
				<mesh filename="meshes/wristy_collision.obj" scale="1.00000 1.00000 1.00000"/>
			</geometry>
		</collision>
		<visual>
			<origin rpy="0.00000 -0.00000 0.00000" xyz="0.00000 -0.00000 0.00000"/>
			<geometry>
				<mesh filename="meshes/wristy.obj" scale="1.00000 1.00000 1.00000"/>
			</geometry>
		</visual>
	</link>
	<link name="link0_4">
		<inertial>
			<origin rpy="0.00000 -0.00000 0.00000" xyz="0.00000 0.00000 0.00000"/>
			<mass value="0.00000"/>
			<inertia ixx="0.00000" ixy="0" ixz="0" iyy="0.00000" iyz="0" izz="0.00000"/>
		</inertial>
	</link>
	<link name="wristx">
		<inertial>
			<origin rpy="-1.55663 -1.51744 -1.43174" xyz="0.00139 -0.00975 -0.00253"/>
			<mass value="0.01069"/>
			<inertia ixx="0.00005" ixy="0" ixz="0" iyy="0.00004" iyz="0" izz="0.00004"/>
		</inertial>
		<collision>
			<origin rpy="0.00000 -0.00000 0.00000" xyz="-0.00000 0.00000 0.00000"/>
			<geometry>
				<mesh filename="meshes/wristx_collision.obj" scale="1.00000 1.00000 1.00000"/>
			</geometry>
		</collision>
		<visual>
			<origin rpy="0.00000 -0.00000 0.00000" xyz="-0.00000 0.00000 0.00000"/>
			<geometry>
				<mesh filename="meshes/wristx.obj" scale="1.00000 1.00000 1.00000"/>
			</geometry>
		</visual>
	</link>
	<link name="link0_6">
		<inertial>
			<origin rpy="0.00000 -0.00000 0.00000" xyz="0.00000 0.00000 0.00000"/>
			<mass value="0.00000"/>
			<inertia ixx="0.00000" ixy="0" ixz="0" iyy="0.00000" iyz="0" izz="0.00000"/>
		</inertial>
	</link>
	<link name="wristz">
		<inertial>
			<origin rpy="1.56681 0.10125 1.56186" xyz="0.00058 -0.00126 0.00046"/>
			<mass value="0.00602"/>
			<inertia ixx="0.00002" ixy="0" ixz="0" iyy="0.00002" iyz="0" izz="0.00002"/>
		</inertial>
		<collision>
			<origin rpy="0.00000 -0.00000 0.00000" xyz="-0.00000 0.00000 -0.00000"/>
			<geometry>
				<mesh filename="meshes/wristz_collision.obj" scale="1.00000 1.00000 1.00000"/>
			</geometry>
		</collision>
		<visual>
			<origin rpy="0.00000 -0.00000 0.00000" xyz="-0.00000 0.00000 -0.00000"/>
			<geometry>
				<mesh filename="meshes/wristz.obj" scale="1.00000 1.00000 1.00000"/>
			</geometry>
		</visual>
	</link>
	<link name="palm">
		<inertial>
			<origin rpy="-2.25401 -1.46740 -0.53897" xyz="-0.02179 -0.03761 0.00277"/>
			<mass value="0.11987"/>
			<inertia ixx="0.00105" ixy="0" ixz="0" iyy="0.00075" iyz="0" izz="0.00076"/>
		</inertial>
		<collision>
			<origin rpy="0.00000 -0.00000 0.00000" xyz="-0.00000 0.00000 0.00000"/>
			<geometry>
				<mesh filename="meshes/palm_collision.obj" scale="1.00000 1.00000 1.00000"/>
			</geometry>
		</collision>
		<visual>
			<origin rpy="0.00000 -0.00000 0.00000" xyz="-0.00000 0.00000 0.00000"/>
			<geometry>
				<mesh filename="meshes/palm.obj" scale="1.00000 1.00000 1.00000"/>
			</geometry>
		</visual>
	</link>
	<link name="link0_9">
		<inertial>
			<origin rpy="0.00000 -0.00000 0.00000" xyz="0.00000 0.00000 0.00000"/>
			<mass value="0.00000"/>
			<inertia ixx="0.00000" ixy="0" ixz="0" iyy="0.00000" iyz="0" izz="0.00000"/>
		</inertial>
	</link>
	<link name="thumb0">
		<inertial>
			<origin rpy="1.76706 -0.09351 1.62823" xyz="0.00863 -0.00016 -0.00095"/>
			<mass value="0.00337"/>
			<inertia ixx="0.00001" ixy="0" ixz="0" iyy="0.00001" iyz="0" izz="0.00001"/>
		</inertial>
		<collision>
			<origin rpy="0.00000 -0.00000 0.00000" xyz="0.00000 0.00000 0.00000"/>
			<geometry>
				<mesh filename="meshes/thumb0_collision.obj" scale="1.00000 1.00000 1.00000"/>
			</geometry>
		</collision>
		<visual>
			<origin rpy="0.00000 -0.00000 0.00000" xyz="0.00000 0.00000 0.00000"/>
			<geometry>
				<mesh filename="meshes/thumb0.obj" scale="1.00000 1.00000 1.00000"/>
			</geometry>
		</visual>
	</link>
	<link name="link0_11">
		<inertial>
			<origin rpy="0.00000 -0.00000 0.00000" xyz="0.00000 0.00000 0.00000"/>
			<mass value="0.00000"/>
			<inertia ixx="0.00000" ixy="0" ixz="0" iyy="0.00000" iyz="0" izz="0.00000"/>
		</inertial>
	</link>
	<link name="thumb1">
		<inertial>
			<origin rpy="1.48128 0.01362 1.58734" xyz="0.01902 0.00036 -0.00019"/>
			<mass value="0.00596"/>
			<inertia ixx="0.00002" ixy="0" ixz="0" iyy="0.00002" iyz="0" izz="0.00001"/>
		</inertial>
		<collision>
			<origin rpy="0.00000 -0.00000 0.00000" xyz="0.00000 0.00000 -0.00000"/>
			<geometry>
				<mesh filename="meshes/thumb1_collision.obj" scale="1.00000 1.00000 1.00000"/>
			</geometry>
		</collision>
		<visual>
			<origin rpy="0.00000 -0.00000 0.00000" xyz="0.00000 0.00000 -0.00000"/>
			<geometry>
				<mesh filename="meshes/thumb1.obj" scale="1.00000 1.00000 1.00000"/>
			</geometry>
		</visual>
	</link>
	<link name="link0_13">
		<inertial>
			<origin rpy="0.00000 -0.00000 0.00000" xyz="0.00000 0.00000 0.00000"/>
			<mass value="0.00000"/>
			<inertia ixx="0.00000" ixy="0" ixz="0" iyy="0.00000" iyz="0" izz="0.00000"/>
		</inertial>
	</link>
	<link name="thumb2">
		<inertial>
			<origin rpy="1.49293 -0.04106 1.59651" xyz="0.01890 0.00038 0.00065"/>
			<mass value="0.00600"/>
			<inertia ixx="0.00002" ixy="0" ixz="0" iyy="0.00002" iyz="0" izz="0.00001"/>
		</inertial>
		<collision>
			<origin rpy="0.00000 -0.00000 0.00000" xyz="0.00000 0.00000 -0.00000"/>
			<geometry>
				<mesh filename="meshes/thumb2_collision.obj" scale="1.00000 1.00000 1.00000"/>
			</geometry>
		</collision>
		<visual>
			<origin rpy="0.00000 -0.00000 0.00000" xyz="0.00000 0.00000 -0.00000"/>
			<geometry>
				<mesh filename="meshes/thumb2.obj" scale="1.00000 1.00000 1.00000"/>
			</geometry>
		</visual>
	</link>
	<link name="link0_15">
		<inertial>
			<origin rpy="0.00000 -0.00000 0.00000" xyz="0.00000 0.00000 0.00000"/>
			<mass value="0.00000"/>
			<inertia ixx="0.00000" ixy="0" ixz="0" iyy="0.00000" iyz="0" izz="0.00000"/>
		</inertial>
	</link>
	<link name="thumb3">
		<inertial>
			<origin rpy="1.49293 -0.04106 1.59651" xyz="0.01890 0.00038 0.00065"/>
			<mass value="0.00600"/>
			<inertia ixx="0.00001" ixy="0" ixz="0" iyy="0.00001" iyz="0" izz="0.00001"/>
		</inertial>
		<collision>
			<origin rpy="0.00000 -0.00000 0.00000" xyz="0.00000 0.00000 -0.00000"/>
			<geometry>
				<mesh filename="meshes/thumb3_collision.obj" scale="1.00000 1.00000 1.00000"/>
			</geometry>
		</collision>
		<visual>
			<origin rpy="0.00000 -0.00000 0.00000" xyz="0.00000 0.00000 -0.00000"/>
			<geometry>
				<mesh filename="meshes/thumb3.obj" scale="1.00000 1.00000 1.00000"/>
			</geometry>
		</visual>
	</link>
	<link name="link0_17">
		<inertial>
			<origin rpy="0.00000 -0.00000 0.00000" xyz="0.00000 0.00000 0.00000"/>
			<mass value="0.00000"/>
			<inertia ixx="0.00000" ixy="0" ixz="0" iyy="0.00000" iyz="0" izz="0.00000"/>
		</inertial>
	</link>
	<link name="index0">
		<inertial>
			<origin rpy="1.59286 -0.02059 0.01812" xyz="-0.00014 -0.00548 0.00021"/>
			<mass value="0.00296"/>
			<inertia ixx="0.00001" ixy="0" ixz="0" iyy="0.00001" iyz="0" izz="0.00001"/>
		</inertial>
		<collision>
			<origin rpy="0.00000 -0.00000 0.00000" xyz="0.00000 0.00000 0.00000"/>
			<geometry>
				<mesh filename="meshes/index0_collision.obj" scale="1.00000 1.00000 1.00000"/>
			</geometry>
		</collision>
		<visual>
			<origin rpy="0.00000 -0.00000 0.00000" xyz="0.00000 0.00000 0.00000"/>
			<geometry>
				<mesh filename="meshes/index0.obj" scale="1.00000 1.00000 1.00000"/>
			</geometry>
		</visual>
	</link>
	<link name="link0_19">
		<inertial>
			<origin rpy="0.00000 -0.00000 0.00000" xyz="0.00000 0.00000 0.00000"/>
			<mass value="0.00000"/>
			<inertia ixx="0.00000" ixy="0" ixz="0" iyy="0.00000" iyz="0" izz="0.00000"/>
		</inertial>
	</link>
	<link name="index1">
		<inertial>
			<origin rpy="1.59512 -0.00910 -0.00273" xyz="0.00041 -0.02131 0.00066"/>
			<mass value="0.00478"/>
			<inertia ixx="0.00001" ixy="0" ixz="0" iyy="0.00001" iyz="0" izz="0.00001"/>
		</inertial>
		<collision>
			<origin rpy="0.00000 -0.00000 0.00000" xyz="-0.00000 0.00000 -0.00000"/>
			<geometry>
				<mesh filename="meshes/index1_collision.obj" scale="1.00000 1.00000 1.00000"/>
			</geometry>
		</collision>
		<visual>
			<origin rpy="0.00000 -0.00000 0.00000" xyz="-0.00000 0.00000 -0.00000"/>
			<geometry>
				<mesh filename="meshes/index1.obj" scale="1.00000 1.00000 1.00000"/>
			</geometry>
		</visual>
	</link>
	<link name="link0_21">
		<inertial>
			<origin rpy="0.00000 -0.00000 0.00000" xyz="0.00000 0.00000 0.00000"/>
			<mass value="0.00000"/>
			<inertia ixx="0.00000" ixy="0" ixz="0" iyy="0.00000" iyz="0" izz="0.00000"/>
		</inertial>
	</link>
	<link name="index2">
		<inertial>
			<origin rpy="1.49016 -0.05885 -0.02032" xyz="-0.00084 -0.01269 0.00057"/>
			<mass value="0.00345"/>
			<inertia ixx="0.00001" ixy="0" ixz="0" iyy="0.00001" iyz="0" izz="0.00001"/>
		</inertial>
		<collision>
			<origin rpy="0.00000 -0.00000 0.00000" xyz="-0.00000 0.00000 0.00000"/>
			<geometry>
				<mesh filename="meshes/index2_collision.obj" scale="1.00000 1.00000 1.00000"/>
			</geometry>
		</collision>
		<visual>
			<origin rpy="0.00000 -0.00000 0.00000" xyz="-0.00000 0.00000 0.00000"/>
			<geometry>
				<mesh filename="meshes/index2.obj" scale="1.00000 1.00000 1.00000"/>
			</geometry>
		</visual>
	</link>
	<link name="link0_23">
		<inertial>
			<origin rpy="0.00000 -0.00000 0.00000" xyz="0.00000 0.00000 0.00000"/>
			<mass value="0.00000"/>
			<inertia ixx="0.00000" ixy="0" ixz="0" iyy="0.00000" iyz="0" izz="0.00000"/>
		</inertial>
	</link>
	<link name="index3">
		<inertial>
			<origin rpy="-0.00887 -1.50417 1.57958" xyz="0.00004 -0.01253 0.00090"/>
			<mass value="0.00274"/>
			<inertia ixx="0.00001" ixy="0" ixz="0" iyy="0.00001" iyz="0" izz="0.00000"/>
		</inertial>
		<collision>
			<origin rpy="0.00000 -0.00000 0.00000" xyz="0.00000 0.00000 -0.00000"/>
			<geometry>
				<mesh filename="meshes/index3_collision.obj" scale="1.00000 1.00000 1.00000"/>
			</geometry>
		</collision>
		<visual>
			<origin rpy="0.00000 -0.00000 0.00000" xyz="0.00000 0.00000 -0.00000"/>
			<geometry>
				<mesh filename="meshes/index3.obj" scale="1.00000 1.00000 1.00000"/>
			</geometry>
		</visual>
	</link>
	<link name="middle0">
		<inertial>
			<origin rpy="1.59286 -0.02059 0.01812" xyz="-0.00014 -0.00548 0.00021"/>
			<mass value="0.00296"/>
			<inertia ixx="0.00001" ixy="0" ixz="0" iyy="0.00001" iyz="0" izz="0.00001"/>
		</inertial>
		<collision>
			<origin rpy="0.00000 -0.00000 0.00000" xyz="0.00000 0.00000 0.00000"/>
			<geometry>
				<mesh filename="meshes/middle0_collision.obj" scale="1.00000 1.00000 1.00000"/>
			</geometry>
		</collision>
		<visual>
			<origin rpy="0.00000 -0.00000 0.00000" xyz="0.00000 0.00000 0.00000"/>
			<geometry>
				<mesh filename="meshes/middle0.obj" scale="1.00000 1.00000 1.00000"/>
			</geometry>
		</visual>
	</link>
	<link name="link0_26">
		<inertial>
			<origin rpy="0.00000 -0.00000 0.00000" xyz="0.00000 0.00000 0.00000"/>
			<mass value="0.00000"/>
			<inertia ixx="0.00000" ixy="0" ixz="0" iyy="0.00000" iyz="0" izz="0.00000"/>
		</inertial>
	</link>
	<link name="middle1">
		<inertial>
			<origin rpy="1.59512 -0.00910 -0.00273" xyz="0.00041 -0.02131 0.00066"/>
			<mass value="0.00478"/>
			<inertia ixx="0.00001" ixy="0" ixz="0" iyy="0.00001" iyz="0" izz="0.00001"/>
		</inertial>
		<collision>
			<origin rpy="0.00000 -0.00000 0.00000" xyz="0.00000 0.00000 0.00000"/>
			<geometry>
				<mesh filename="meshes/middle1_collision.obj" scale="1.00000 1.00000 1.00000"/>
			</geometry>
		</collision>
		<visual>
			<origin rpy="0.00000 -0.00000 0.00000" xyz="0.00000 0.00000 0.00000"/>
			<geometry>
				<mesh filename="meshes/middle1.obj" scale="1.00000 1.00000 1.00000"/>
			</geometry>
		</visual>
	</link>
	<link name="link0_28">
		<inertial>
			<origin rpy="0.00000 -0.00000 0.00000" xyz="0.00000 0.00000 0.00000"/>
			<mass value="0.00000"/>
			<inertia ixx="0.00000" ixy="0" ixz="0" iyy="0.00000" iyz="0" izz="0.00000"/>
		</inertial>
	</link>
	<link name="middle2">
		<inertial>
			<origin rpy="1.49015 -0.05874 -0.02033" xyz="-0.00084 -0.01269 0.00057"/>
			<mass value="0.00345"/>
			<inertia ixx="0.00001" ixy="0" ixz="0" iyy="0.00001" iyz="0" izz="0.00001"/>
		</inertial>
		<collision>
			<origin rpy="0.00000 -0.00000 0.00000" xyz="0.00000 -0.00000 -0.00000"/>
			<geometry>
				<mesh filename="meshes/middle2_collision.obj" scale="1.00000 1.00000 1.00000"/>
			</geometry>
		</collision>
		<visual>
			<origin rpy="0.00000 -0.00000 0.00000" xyz="0.00000 -0.00000 -0.00000"/>
			<geometry>
				<mesh filename="meshes/middle2.obj" scale="1.00000 1.00000 1.00000"/>
			</geometry>
		</visual>
	</link>
	<link name="link0_30">
		<inertial>
			<origin rpy="0.00000 -0.00000 0.00000" xyz="0.00000 0.00000 0.00000"/>
			<mass value="0.00000"/>
			<inertia ixx="0.00000" ixy="0" ixz="0" iyy="0.00000" iyz="0" izz="0.00000"/>
		</inertial>
	</link>
	<link name="middle3">
		<inertial>
			<origin rpy="-0.00814 -1.50417 1.57884" xyz="0.00004 -0.01253 0.00090"/>
			<mass value="0.00274"/>
			<inertia ixx="0.00001" ixy="0" ixz="0" iyy="0.00001" iyz="0" izz="0.00000"/>
		</inertial>
		<collision>
			<origin rpy="0.00000 -0.00000 0.00000" xyz="-0.00000 -0.00000 -0.00000"/>
			<geometry>
				<mesh filename="meshes/middle3_collision.obj" scale="1.00000 1.00000 1.00000"/>
			</geometry>
		</collision>
		<visual>
			<origin rpy="0.00000 -0.00000 0.00000" xyz="-0.00000 -0.00000 -0.00000"/>
			<geometry>
				<mesh filename="meshes/middle3.obj" scale="1.00000 1.00000 1.00000"/>
			</geometry>
		</visual>
	</link>
	<link name="link0_32">
		<inertial>
			<origin rpy="0.00000 -0.00000 0.00000" xyz="0.00000 0.00000 0.00000"/>
			<mass value="0.00000"/>
			<inertia ixx="0.00000" ixy="0" ixz="0" iyy="0.00000" iyz="0" izz="0.00000"/>
		</inertial>
	</link>
	<link name="ring0">
		<inertial>
			<origin rpy="1.59286 -0.02058 0.01812" xyz="-0.00014 -0.00548 0.00021"/>
			<mass value="0.00296"/>
			<inertia ixx="0.00001" ixy="0" ixz="0" iyy="0.00001" iyz="0" izz="0.00001"/>
		</inertial>
		<collision>
			<origin rpy="0.00000 -0.00000 0.00000" xyz="0.00000 -0.00000 0.00000"/>
			<geometry>
				<mesh filename="meshes/ring0_collision.obj" scale="1.00000 1.00000 1.00000"/>
			</geometry>
		</collision>
		<visual>
			<origin rpy="0.00000 -0.00000 0.00000" xyz="0.00000 -0.00000 0.00000"/>
			<geometry>
				<mesh filename="meshes/ring0.obj" scale="1.00000 1.00000 1.00000"/>
			</geometry>
		</visual>
	</link>
	<link name="link0_34">
		<inertial>
			<origin rpy="0.00000 -0.00000 0.00000" xyz="0.00000 0.00000 0.00000"/>
			<mass value="0.00000"/>
			<inertia ixx="0.00000" ixy="0" ixz="0" iyy="0.00000" iyz="0" izz="0.00000"/>
		</inertial>
	</link>
	<link name="ring1">
		<inertial>
			<origin rpy="1.59512 -0.00911 -0.00273" xyz="0.00041 -0.02131 0.00066"/>
			<mass value="0.00478"/>
			<inertia ixx="0.00001" ixy="0" ixz="0" iyy="0.00001" iyz="0" izz="0.00001"/>
		</inertial>
		<collision>
			<origin rpy="0.00000 -0.00000 0.00000" xyz="-0.00000 0.00000 0.00000"/>
			<geometry>
				<mesh filename="meshes/ring1_collision.obj" scale="1.00000 1.00000 1.00000"/>
			</geometry>
		</collision>
		<visual>
			<origin rpy="0.00000 -0.00000 0.00000" xyz="-0.00000 0.00000 0.00000"/>
			<geometry>
				<mesh filename="meshes/ring1.obj" scale="1.00000 1.00000 1.00000"/>
			</geometry>
		</visual>
	</link>
	<link name="link0_36">
		<inertial>
			<origin rpy="0.00000 -0.00000 0.00000" xyz="0.00000 0.00000 0.00000"/>
			<mass value="0.00000"/>
			<inertia ixx="0.00000" ixy="0" ixz="0" iyy="0.00000" iyz="0" izz="0.00000"/>
		</inertial>
	</link>
	<link name="ring2">
		<inertial>
			<origin rpy="1.49016 -0.05905 -0.02030" xyz="-0.00084 -0.01269 0.00057"/>
			<mass value="0.00345"/>
			<inertia ixx="0.00001" ixy="0" ixz="0" iyy="0.00001" iyz="0" izz="0.00001"/>
		</inertial>
		<collision>
			<origin rpy="0.00000 -0.00000 0.00000" xyz="0.00000 0.00000 0.00000"/>
			<geometry>
				<mesh filename="meshes/ring2_collision.obj" scale="1.00000 1.00000 1.00000"/>
			</geometry>
		</collision>
		<visual>
			<origin rpy="0.00000 -0.00000 0.00000" xyz="0.00000 0.00000 0.00000"/>
			<geometry>
				<mesh filename="meshes/ring2.obj" scale="1.00000 1.00000 1.00000"/>
			</geometry>
		</visual>
	</link>
	<link name="link0_38">
		<inertial>
			<origin rpy="0.00000 -0.00000 0.00000" xyz="0.00000 0.00000 0.00000"/>
			<mass value="0.00000"/>
			<inertia ixx="0.00000" ixy="0" ixz="0" iyy="0.00000" iyz="0" izz="0.00000"/>
		</inertial>
	</link>
	<link name="ring3">
		<inertial>
			<origin rpy="-0.00870 -1.50417 1.57940" xyz="0.00004 -0.01253 0.00090"/>
			<mass value="0.00274"/>
			<inertia ixx="0.00001" ixy="0" ixz="0" iyy="0.00001" iyz="0" izz="0.00000"/>
		</inertial>
		<collision>
			<origin rpy="0.00000 -0.00000 0.00000" xyz="0.00000 0.00000 0.00000"/>
			<geometry>
				<mesh filename="meshes/ring3_collision.obj" scale="1.00000 1.00000 1.00000"/>
			</geometry>
		</collision>
		<visual>
			<origin rpy="0.00000 -0.00000 0.00000" xyz="0.00000 0.00000 0.00000"/>
			<geometry>
				<mesh filename="meshes/ring3.obj" scale="1.00000 1.00000 1.00000"/>
			</geometry>
		</visual>
	</link>
	<link name="link0_40">
		<inertial>
			<origin rpy="0.00000 -0.00000 0.00000" xyz="0.00000 0.00000 0.00000"/>
			<mass value="0.00000"/>
			<inertia ixx="0.00000" ixy="0" ixz="0" iyy="0.00000" iyz="0" izz="0.00000"/>
		</inertial>
	</link>
	<link name="pinky0">
		<inertial>
			<origin rpy="1.59286 -0.02058 0.01812" xyz="-0.00014 -0.00538 0.00021"/>
			<mass value="0.00296"/>
			<inertia ixx="0.00001" ixy="0" ixz="0" iyy="0.00001" iyz="0" izz="0.00001"/>
		</inertial>
		<collision>
			<origin rpy="0.00000 -0.00000 0.00000" xyz="0.00000 0.00000 0.00000"/>
			<geometry>
				<mesh filename="meshes/pinky0_collision.obj" scale="1.00000 1.00000 1.00000"/>
			</geometry>
		</collision>
		<visual>
			<origin rpy="0.00000 -0.00000 0.00000" xyz="0.00000 0.00000 0.00000"/>
			<geometry>
				<mesh filename="meshes/pinky0.obj" scale="1.00000 1.00000 1.00000"/>
			</geometry>
		</visual>
	</link>
	<link name="link0_42">
		<inertial>
			<origin rpy="0.00000 -0.00000 0.00000" xyz="0.00000 0.00000 0.00000"/>
			<mass value="0.00000"/>
			<inertia ixx="0.00000" ixy="0" ixz="0" iyy="0.00000" iyz="0" izz="0.00000"/>
		</inertial>
	</link>
	<link name="pinky1">
		<inertial>
			<origin rpy="1.62960 0.06859 -0.00625" xyz="0.00046 -0.01605 0.00092"/>
			<mass value="0.00341"/>
			<inertia ixx="0.00001" ixy="0" ixz="0" iyy="0.00001" iyz="0" izz="0.00001"/>
		</inertial>
		<collision>
			<origin rpy="0.00000 -0.00000 0.00000" xyz="0.00000 0.00000 0.00000"/>
			<geometry>
				<mesh filename="meshes/pinky1_collision.obj" scale="1.00000 1.00000 1.00000"/>
			</geometry>
		</collision>
		<visual>
			<origin rpy="0.00000 -0.00000 0.00000" xyz="0.00000 0.00000 0.00000"/>
			<geometry>
				<mesh filename="meshes/pinky1.obj" scale="1.00000 1.00000 1.00000"/>
			</geometry>
		</visual>
	</link>
	<link name="link0_44">
		<inertial>
			<origin rpy="0.00000 -0.00000 0.00000" xyz="0.00000 0.00000 0.00000"/>
			<mass value="0.00000"/>
			<inertia ixx="0.00000" ixy="0" ixz="0" iyy="0.00000" iyz="0" izz="0.00000"/>
		</inertial>
	</link>
	<link name="pinky2">
		<inertial>
			<origin rpy="1.45350 0.03711 -0.04187" xyz="-0.00027 -0.00915 0.00074"/>
			<mass value="0.00251"/>
			<inertia ixx="0.00001" ixy="0" ixz="0" iyy="0.00001" iyz="0" izz="0.00001"/>
		</inertial>
		<collision>
			<origin rpy="0.00000 -0.00000 0.00000" xyz="-0.00000 -0.00000 0.00000"/>
			<geometry>
				<mesh filename="meshes/pinky2_collision.obj" scale="1.00000 1.00000 1.00000"/>
			</geometry>
		</collision>
		<visual>
			<origin rpy="0.00000 -0.00000 0.00000" xyz="-0.00000 -0.00000 0.00000"/>
			<geometry>
				<mesh filename="meshes/pinky2.obj" scale="1.00000 1.00000 1.00000"/>
			</geometry>
		</visual>
	</link>
	<link name="link0_46">
		<inertial>
			<origin rpy="0.00000 -0.00000 0.00000" xyz="0.00000 0.00000 0.00000"/>
			<mass value="0.00000"/>
			<inertia ixx="0.00000" ixy="0" ixz="0" iyy="0.00000" iyz="0" izz="0.00000"/>
		</inertial>
	</link>
	<link name="pinky3">
		<inertial>
			<origin rpy="0.03154 -1.50676 1.54007" xyz="0.00004 -0.01250 0.00091"/>
			<mass value="0.00273"/>
			<inertia ixx="0.00001" ixy="0" ixz="0" iyy="0.00001" iyz="0" izz="0.00000"/>
		</inertial>
		<collision>
			<origin rpy="0.00000 -0.00000 0.00000" xyz="-0.00000 0.00000 -0.00000"/>
			<geometry>
				<mesh filename="meshes/pinky3_collision.obj" scale="1.00000 1.00000 1.00000"/>
			</geometry>
		</collision>
		<visual>
			<origin rpy="0.00000 -0.00000 0.00000" xyz="-0.00000 0.00000 -0.00000"/>
			<geometry>
				<mesh filename="meshes/pinky3.obj" scale="1.00000 1.00000 1.00000"/>
			</geometry>
		</visual>
	</link>
	<joint name="wrist_PRO" type="continuous">
		<parent link="forearm"/>
		<child link="link0_2"/>
		<dynamics damping="1.0" friction="0.0001"/>
		<origin rpy="0.00000 -0.00000 0.00000" xyz="0.00000 0.00000 0.00000"/>
		<axis xyz="0.00000 1.00000 0.00000"/>
	</joint>
	<joint name="jointfix_23_2" type="fixed">
		<parent link="link0_2"/>
		<child link="wristy"/>
		<dynamics damping="1.0" friction="0.0001"/>
		<origin rpy="0.00000 -0.00000 0.00000" xyz="0.00000 0.00000 0.00000"/>
		<axis xyz="0.00000 0.00000 0.00000"/>
	</joint>
	<joint name="wrist_UDEV" type="continuous">
		<parent link="wristy"/>
		<child link="link0_4"/>
		<dynamics damping="1.0" friction="0.0001"/>
		<origin rpy="-0.00000 -0.00000 -0.00000" xyz="-0.00003 -0.04765 0.00204"/>
		<axis xyz="0.00000 0.00000 -1.00000"/>
	</joint>
	<joint name="jointfix_22_4" type="fixed">
		<parent link="link0_4"/>
		<child link="wristx"/>
		<dynamics damping="1.0" friction="0.0001"/>
		<origin rpy="0.00000 -0.00000 0.00000" xyz="0.00000 0.00000 0.00000"/>
		<axis xyz="0.00000 0.00000 0.00000"/>
	</joint>
	<joint name="wrist_FLEX" type="continuous">
		<parent link="wristx"/>
		<child link="link0_6"/>
		<dynamics damping="1.0" friction="0.0001"/>
		<origin rpy="0.00000 -0.00000 0.00000" xyz="0.00019 -0.03000 -0.00209"/>
		<axis xyz="1.00000 0.00000 0.00000"/>
	</joint>
	<joint name="jointfix_21_6" type="fixed">
		<parent link="link0_6"/>
		<child link="wristz"/>
		<dynamics damping="1.0" friction="0.0001"/>
		<origin rpy="0.00000 -0.00000 0.00000" xyz="0.00000 0.00000 0.00000"/>
		<axis xyz="0.00000 0.00000 0.00000"/>
	</joint>
	<joint name="jointfix_20_5" type="fixed">
		<parent link="wristz"/>
		<child link="palm"/>
		<dynamics damping="1.0" friction="0.0001"/>
		<origin rpy="0.00000 -0.00000 0.00000" xyz="0.02562 -0.00000 -0.00000"/>
		<axis xyz="0.00000 0.00000 0.00000"/>
	</joint>
	<joint name="thumb_ABD" type="continuous">
		<parent link="palm"/>
		<child link="link0_9"/>
		<dynamics damping="1.0" friction="0.0001"/>
		<origin rpy="0.08738 -0.03058 -0.26537" xyz="0.00836 -0.02070 -0.01009"/>
		<axis xyz="0.00000 1.00000 0.00000"/>
	</joint>
	<joint name="jointfix_3_9" type="fixed">
		<parent link="link0_9"/>
		<child link="thumb0"/>
		<dynamics damping="1.0" friction="0.0001"/>
		<origin rpy="0.00000 -0.00000 0.00000" xyz="0.00000 0.00000 0.00000"/>
		<axis xyz="0.00000 0.00000 0.00000"/>
	</joint>
	<joint name="thumb_MCP" type="continuous">
		<parent link="thumb0"/>
		<child link="link0_11"/>
		<dynamics damping="1.0" friction="0.0001"/>
		<origin rpy="0.00000 -0.00000 0.00000" xyz="0.02092 -0.00084 0.00145"/>
		<axis xyz="0.00000 0.00000 -1.00000"/>
	</joint>
	<joint name="jointfix_2_11" type="fixed">
		<parent link="link0_11"/>
		<child link="thumb1"/>
		<dynamics damping="1.0" friction="0.0001"/>
		<origin rpy="0.00000 -0.00000 0.00000" xyz="0.00000 0.00000 0.00000"/>
		<axis xyz="0.00000 0.00000 0.00000"/>
	</joint>
	<joint name="thumb_PIP" type="continuous">
		<parent link="thumb1"/>
		<child link="link0_13"/>
		<dynamics damping="1.0" friction="0.0001"/>
		<origin rpy="-0.00000 -0.00000 -0.00000" xyz="0.03350 -0.00000 -0.00074"/>
		<axis xyz="0.00000 0.00000 -1.00000"/>
	</joint>
	<joint name="jointfix_1_13" type="fixed">
		<parent link="link0_13"/>
		<child link="thumb2"/>
		<dynamics damping="1.0" friction="0.0001"/>
		<origin rpy="0.00000 -0.00000 0.00000" xyz="0.00000 0.00000 0.00000"/>
		<axis xyz="0.00000 0.00000 0.00000"/>
	</joint>
	<joint name="thumb_DIP" type="continuous">
		<parent link="thumb2"/>
		<child link="link0_15"/>
		<dynamics damping="1.0" friction="0.0001"/>
		<origin rpy="-0.00000 -0.00000 0.00000" xyz="0.03350 -0.00000 0.00109"/>
		<axis xyz="0.00000 0.00000 -1.00000"/>
	</joint>
	<joint name="jointfix_0_15" type="fixed">
		<parent link="link0_15"/>
		<child link="thumb3"/>
		<dynamics damping="1.0" friction="0.0001"/>
		<origin rpy="0.00000 -0.00000 0.00000" xyz="0.00000 0.00000 0.00000"/>
		<axis xyz="0.00000 0.00000 0.00000"/>
	</joint>
	<joint name="index_ABD" type="continuous">
		<parent link="palm"/>
		<child link="link0_17"/>
		<dynamics damping="1.0" friction="0.0001"/>
		<origin rpy="-0.00000 0.17453 -0.00000" xyz="0.00986 -0.06580 0.00101"/>
		<axis xyz="0.00000 0.00000 1.00000"/>
	</joint>
	<joint name="jointfix_7_17" type="fixed">
		<parent link="link0_17"/>
		<child link="index0"/>
		<dynamics damping="1.0" friction="0.0001"/>
		<origin rpy="0.00000 -0.00000 0.00000" xyz="0.00000 0.00000 0.00000"/>
		<axis xyz="0.00000 0.00000 0.00000"/>
	</joint>
	<joint name="index_MCP" type="continuous">
		<parent link="index0"/>
		<child link="link0_19"/>
		<dynamics damping="1.0" friction="0.0001"/>
		<origin rpy="-0.00000 -0.00000 -0.00000" xyz="0.00006 -0.01800 -0.00000"/>
		<axis xyz="1.00000 0.00000 0.00000"/>
	</joint>
	<joint name="jointfix_6_19" type="fixed">
		<parent link="link0_19"/>
		<child link="index1"/>
		<dynamics damping="1.0" friction="0.0001"/>
		<origin rpy="0.00000 -0.00000 0.00000" xyz="0.00000 0.00000 0.00000"/>
		<axis xyz="0.00000 0.00000 0.00000"/>
	</joint>
	<joint name="index_PIP" type="continuous">
		<parent link="index1"/>
		<child link="link0_21"/>
		<dynamics damping="1.0" friction="0.0001"/>
		<origin rpy="0.00000 -0.00000 0.00000" xyz="0.00109 -0.04350 0.00050"/>
		<axis xyz="1.00000 0.00000 0.00000"/>
	</joint>
	<joint name="jointfix_5_21" type="fixed">
		<parent link="link0_21"/>
		<child link="index2"/>
		<dynamics damping="1.0" friction="0.0001"/>
		<origin rpy="0.00000 -0.00000 0.00000" xyz="0.00000 0.00000 0.00000"/>
		<axis xyz="0.00000 0.00000 0.00000"/>
	</joint>
	<joint name="index_DIP" type="continuous">
		<parent link="index2"/>
		<child link="link0_23"/>
		<dynamics damping="1.0" friction="0.0001"/>
		<origin rpy="0.00000 -0.00000 -0.00000" xyz="-0.00063 -0.02450 -0.00000"/>
		<axis xyz="1.00000 0.00000 0.00000"/>
	</joint>
	<joint name="jointfix_4_23" type="fixed">
		<parent link="link0_23"/>
		<child link="index3"/>
		<dynamics damping="1.0" friction="0.0001"/>
		<origin rpy="0.00000 -0.00000 0.00000" xyz="0.00000 0.00000 0.00000"/>
		<axis xyz="0.00000 0.00000 0.00000"/>
	</joint>
	<joint name="jointfix_11_7" type="fixed">
		<parent link="palm"/>
		<child link="middle0"/>
		<dynamics damping="1.0" friction="0.0001"/>
		<origin rpy="-0.02778 -0.00000 0.00000" xyz="-0.01281 -0.07790 0.00545"/>
		<axis xyz="0.00000 0.00000 0.00000"/>
	</joint>
	<joint name="middle_MCP" type="continuous">
		<parent link="middle0"/>
		<child link="link0_26"/>
		<dynamics damping="1.0" friction="0.0001"/>
		<origin rpy="-0.00000 0.00000 -0.00000" xyz="0.00006 -0.01800 -0.00000"/>
		<axis xyz="1.00000 0.00000 0.00000"/>
	</joint>
	<joint name="jointfix_10_26" type="fixed">
		<parent link="link0_26"/>
		<child link="middle1"/>
		<dynamics damping="1.0" friction="0.0001"/>
		<origin rpy="0.00000 -0.00000 0.00000" xyz="0.00000 0.00000 0.00000"/>
		<axis xyz="0.00000 0.00000 0.00000"/>
	</joint>
	<joint name="middle_PIP" type="continuous">
		<parent link="middle1"/>
		<child link="link0_28"/>
		<dynamics damping="1.0" friction="0.0001"/>
		<origin rpy="-0.00000 0.00000 -0.00000" xyz="0.00109 -0.04350 0.00050"/>
		<axis xyz="1.00000 0.00000 0.00000"/>
	</joint>
	<joint name="jointfix_9_28" type="fixed">
		<parent link="link0_28"/>
		<child link="middle2"/>
		<dynamics damping="1.0" friction="0.0001"/>
		<origin rpy="0.00000 -0.00000 0.00000" xyz="0.00000 0.00000 0.00000"/>
		<axis xyz="0.00000 0.00000 0.00000"/>
	</joint>
	<joint name="middle_DIP" type="continuous">
		<parent link="middle2"/>
		<child link="link0_30"/>
		<dynamics damping="1.0" friction="0.0001"/>
		<origin rpy="0.00000 -0.00000 0.00000" xyz="-0.00063 -0.02450 0.00000"/>
		<axis xyz="1.00000 0.00000 0.00000"/>
	</joint>
	<joint name="jointfix_8_30" type="fixed">
		<parent link="link0_30"/>
		<child link="middle3"/>
		<dynamics damping="1.0" friction="0.0001"/>
		<origin rpy="0.00000 -0.00000 0.00000" xyz="0.00000 0.00000 0.00000"/>
		<axis xyz="0.00000 0.00000 0.00000"/>
	</joint>
	<joint name="ring_ABD" type="continuous">
		<parent link="palm"/>
		<child link="link0_32"/>
		<dynamics damping="1.0" friction="0.0001"/>
		<origin rpy="0.00000 -0.17453 -0.00000" xyz="-0.03549 -0.06670 0.00151"/>
		<axis xyz="0.00000 0.00000 -1.00000"/>
	</joint>
	<joint name="jointfix_15_32" type="fixed">
		<parent link="link0_32"/>
		<child link="ring0"/>
		<dynamics damping="1.0" friction="0.0001"/>
		<origin rpy="0.00000 -0.00000 0.00000" xyz="0.00000 0.00000 0.00000"/>
		<axis xyz="0.00000 0.00000 0.00000"/>
	</joint>
	<joint name="ring_MCP" type="continuous">
		<parent link="ring0"/>
		<child link="link0_34"/>
		<dynamics damping="1.0" friction="0.0001"/>
		<origin rpy="-0.00000 0.00000 -0.00000" xyz="0.00006 -0.01800 -0.00000"/>
		<axis xyz="1.00000 0.00000 0.00000"/>
	</joint>
	<joint name="jointfix_14_34" type="fixed">
		<parent link="link0_34"/>
		<child link="ring1"/>
		<dynamics damping="1.0" friction="0.0001"/>
		<origin rpy="0.00000 -0.00000 0.00000" xyz="0.00000 0.00000 0.00000"/>
		<axis xyz="0.00000 0.00000 0.00000"/>
	</joint>
	<joint name="ring_PIP" type="continuous">
		<parent link="ring1"/>
		<child link="link0_36"/>
		<dynamics damping="1.0" friction="0.0001"/>
		<origin rpy="-0.00000 0.00000 -0.00000" xyz="0.00109 -0.04350 0.00050"/>
		<axis xyz="1.00000 0.00000 0.00000"/>
	</joint>
	<joint name="jointfix_13_36" type="fixed">
		<parent link="link0_36"/>
		<child link="ring2"/>
		<dynamics damping="1.0" friction="0.0001"/>
		<origin rpy="0.00000 -0.00000 0.00000" xyz="0.00000 0.00000 0.00000"/>
		<axis xyz="0.00000 0.00000 0.00000"/>
	</joint>
	<joint name="ring_DIP" type="continuous">
		<parent link="ring2"/>
		<child link="link0_38"/>
		<dynamics damping="1.0" friction="0.0001"/>
		<origin rpy="-0.00000 0.00000 -0.00000" xyz="-0.00064 -0.02450 -0.00000"/>
		<axis xyz="1.00000 0.00000 0.00000"/>
	</joint>
	<joint name="jointfix_12_38" type="fixed">
		<parent link="link0_38"/>
		<child link="ring3"/>
		<dynamics damping="1.0" friction="0.0001"/>
		<origin rpy="0.00000 -0.00000 0.00000" xyz="0.00000 0.00000 0.00000"/>
		<axis xyz="0.00000 0.00000 0.00000"/>
	</joint>
	<joint name="pinky_ABD" type="continuous">
		<parent link="palm"/>
		<child link="link0_40"/>
		<dynamics damping="1.0" friction="0.0001"/>
		<origin rpy="0.00000 -0.17453 -0.00000" xyz="-0.05625 -0.05540 -0.00564"/>
		<axis xyz="0.00000 0.00000 -1.00000"/>
	</joint>
	<joint name="jointfix_19_40" type="fixed">
		<parent link="link0_40"/>
		<child link="pinky0"/>
		<dynamics damping="1.0" friction="0.0001"/>
		<origin rpy="0.00000 -0.00000 0.00000" xyz="0.00000 0.00000 0.00000"/>
		<axis xyz="0.00000 0.00000 0.00000"/>
	</joint>
	<joint name="pinky_MCP" type="continuous">
		<parent link="pinky0"/>
		<child link="link0_42"/>
		<dynamics damping="1.0" friction="0.0001"/>
		<origin rpy="-0.00000 -0.00000 -0.00000" xyz="0.00006 -0.01790 -0.00000"/>
		<axis xyz="1.00000 0.00000 0.00000"/>
	</joint>
	<joint name="jointfix_18_42" type="fixed">
		<parent link="link0_42"/>
		<child link="pinky1"/>
		<dynamics damping="1.0" friction="0.0001"/>
		<origin rpy="0.00000 -0.00000 0.00000" xyz="0.00000 0.00000 0.00000"/>
		<axis xyz="0.00000 0.00000 0.00000"/>
	</joint>
	<joint name="pinky_PIP" type="continuous">
		<parent link="pinky1"/>
		<child link="link0_44"/>
		<dynamics damping="1.0" friction="0.0001"/>
		<origin rpy="0.00000 0.00000 0.00000" xyz="0.00058 -0.03300 0.00050"/>
		<axis xyz="1.00000 0.00000 0.00000"/>
	</joint>
	<joint name="jointfix_17_44" type="fixed">
		<parent link="link0_44"/>
		<child link="pinky2"/>
		<dynamics damping="1.0" friction="0.0001"/>
		<origin rpy="0.00000 -0.00000 0.00000" xyz="0.00000 0.00000 0.00000"/>
		<axis xyz="0.00000 0.00000 0.00000"/>
	</joint>
	<joint name="pinky_DIP" type="continuous">
		<parent link="pinky2"/>
		<child link="link0_46"/>
		<dynamics damping="1.0" friction="0.0001"/>
		<origin rpy="-0.00000 0.00000 0.00000" xyz="-0.00005 -0.01750 -0.00000"/>
		<axis xyz="1.00000 0.00000 0.00000"/>
	</joint>
	<joint name="jointfix_16_46" type="fixed">
		<parent link="link0_46"/>
		<child link="pinky3"/>
		<dynamics damping="1.0" friction="0.0001"/>
		<origin rpy="0.00000 -0.00000 0.00000" xyz="0.00000 0.00000 0.00000"/>
		<axis xyz="0.00000 0.00000 0.00000"/>
	</joint>
</robot>
